[2022-04-18 15:25:44,446] {taskinstance.py:1032} INFO - Dependencies all met for <TaskInstance: LocalIngestionDag.wget manual__2022-04-18T15:25:43.017642+00:00 [queued]>
[2022-04-18 15:25:44,455] {taskinstance.py:1032} INFO - Dependencies all met for <TaskInstance: LocalIngestionDag.wget manual__2022-04-18T15:25:43.017642+00:00 [queued]>
[2022-04-18 15:25:44,455] {taskinstance.py:1238} INFO - 
--------------------------------------------------------------------------------
[2022-04-18 15:25:44,455] {taskinstance.py:1239} INFO - Starting attempt 1 of 1
[2022-04-18 15:25:44,455] {taskinstance.py:1240} INFO - 
--------------------------------------------------------------------------------
[2022-04-18 15:25:44,465] {taskinstance.py:1259} INFO - Executing <Task(BashOperator): wget> on 2022-04-18 15:25:43.017642+00:00
[2022-04-18 15:25:44,470] {standard_task_runner.py:52} INFO - Started process 1326 to run task
[2022-04-18 15:25:44,473] {standard_task_runner.py:76} INFO - Running: ['***', 'tasks', 'run', 'LocalIngestionDag', 'wget', 'manual__2022-04-18T15:25:43.017642+00:00', '--job-id', '76', '--raw', '--subdir', 'DAGS_FOLDER/data_ingestion_local.py', '--cfg-path', '/tmp/tmpws_zgki9', '--error-file', '/tmp/tmp1tjxhjhp']
[2022-04-18 15:25:44,474] {standard_task_runner.py:77} INFO - Job 76: Subtask wget
[2022-04-18 15:25:44,528] {logging_mixin.py:109} INFO - Running <TaskInstance: LocalIngestionDag.wget manual__2022-04-18T15:25:43.017642+00:00 [running]> on host 0fb3f3a72b51
[2022-04-18 15:25:44,562] {warnings.py:110} WARNING - /home/***/.local/lib/python3.7/site-packages/***/utils/context.py:152: AirflowContextDeprecationWarning: Accessing 'execution_date' from the template is deprecated and will be removed in a future version. Please use 'data_interval_start' or 'logical_date' instead.
  warnings.warn(_create_deprecation_warning(key, self._deprecation_replacements[key]))

[2022-04-18 15:25:44,581] {taskinstance.py:1426} INFO - Exporting the following env vars:
AIRFLOW_CTX_DAG_OWNER=***
AIRFLOW_CTX_DAG_ID=LocalIngestionDag
AIRFLOW_CTX_TASK_ID=wget
AIRFLOW_CTX_EXECUTION_DATE=2022-04-18T15:25:43.017642+00:00
AIRFLOW_CTX_DAG_RUN_ID=manual__2022-04-18T15:25:43.017642+00:00
[2022-04-18 15:25:44,582] {subprocess.py:62} INFO - Tmp dir root location: 
 /tmp
[2022-04-18 15:25:44,582] {subprocess.py:74} INFO - Running command: ['bash', '-c', 'curl -sSL https://s3.amazonaws.com/nyc-tlc/trip+data/yellow_tripdata_2021-01.csv > /opt/***/output_2022-04.csv']
[2022-04-18 15:25:44,592] {subprocess.py:85} INFO - Output:
[2022-04-18 16:12:29,656] {subprocess.py:89} INFO - curl: (56) OpenSSL SSL_read: SSL_ERROR_SYSCALL, errno 104
[2022-04-18 16:12:29,677] {subprocess.py:93} INFO - Command exited with return code 56
[2022-04-18 16:12:29,715] {taskinstance.py:1700} ERROR - Task failed with exception
Traceback (most recent call last):
  File "/home/airflow/.local/lib/python3.7/site-packages/airflow/models/taskinstance.py", line 1329, in _run_raw_task
    self._execute_task_with_callbacks(context)
  File "/home/airflow/.local/lib/python3.7/site-packages/airflow/models/taskinstance.py", line 1455, in _execute_task_with_callbacks
    result = self._execute_task(context, self.task)
  File "/home/airflow/.local/lib/python3.7/site-packages/airflow/models/taskinstance.py", line 1511, in _execute_task
    result = execute_callable(context=context)
  File "/home/airflow/.local/lib/python3.7/site-packages/airflow/operators/bash.py", line 188, in execute
    f'Bash command failed. The command returned a non-zero exit code {result.exit_code}.'
airflow.exceptions.AirflowException: Bash command failed. The command returned a non-zero exit code 56.
[2022-04-18 16:12:29,732] {taskinstance.py:1277} INFO - Marking task as FAILED. dag_id=LocalIngestionDag, task_id=wget, execution_date=20220418T152543, start_date=20220418T152544, end_date=20220418T161229
[2022-04-18 16:12:29,751] {standard_task_runner.py:92} ERROR - Failed to execute job 76 for task wget
Traceback (most recent call last):
  File "/home/airflow/.local/lib/python3.7/site-packages/airflow/task/task_runner/standard_task_runner.py", line 85, in _start_by_fork
    args.func(args, dag=self.dag)
  File "/home/airflow/.local/lib/python3.7/site-packages/airflow/cli/cli_parser.py", line 48, in command
    return func(*args, **kwargs)
  File "/home/airflow/.local/lib/python3.7/site-packages/airflow/utils/cli.py", line 92, in wrapper
    return f(*args, **kwargs)
  File "/home/airflow/.local/lib/python3.7/site-packages/airflow/cli/commands/task_command.py", line 298, in task_run
    _run_task_by_selected_method(args, dag, ti)
  File "/home/airflow/.local/lib/python3.7/site-packages/airflow/cli/commands/task_command.py", line 107, in _run_task_by_selected_method
    _run_raw_task(args, ti)
  File "/home/airflow/.local/lib/python3.7/site-packages/airflow/cli/commands/task_command.py", line 184, in _run_raw_task
    error_file=args.error_file,
  File "/home/airflow/.local/lib/python3.7/site-packages/airflow/utils/session.py", line 70, in wrapper
    return func(*args, session=session, **kwargs)
  File "/home/airflow/.local/lib/python3.7/site-packages/airflow/models/taskinstance.py", line 1329, in _run_raw_task
    self._execute_task_with_callbacks(context)
  File "/home/airflow/.local/lib/python3.7/site-packages/airflow/models/taskinstance.py", line 1455, in _execute_task_with_callbacks
    result = self._execute_task(context, self.task)
  File "/home/airflow/.local/lib/python3.7/site-packages/airflow/models/taskinstance.py", line 1511, in _execute_task
    result = execute_callable(context=context)
  File "/home/airflow/.local/lib/python3.7/site-packages/airflow/operators/bash.py", line 188, in execute
    f'Bash command failed. The command returned a non-zero exit code {result.exit_code}.'
airflow.exceptions.AirflowException: Bash command failed. The command returned a non-zero exit code 56.
[2022-04-18 16:12:29,788] {local_task_job.py:154} INFO - Task exited with return code 1
[2022-04-18 16:12:29,823] {local_task_job.py:264} INFO - 0 downstream tasks scheduled from follow-on schedule check
